Internal Server Error: /
Traceback (most recent call last):
  File "C:\Users\Crn96\Desktop\client proj\poolmasters\senv\lib\site-packages\django\core\handlers\exception.py", line 56, in inner
    response = get_response(request)
  File "C:\Users\Crn96\Desktop\client proj\poolmasters\senv\lib\site-packages\django\core\handlers\base.py", line 197, in _get_response
    response = wrapped_callback(request, *callback_args, **callback_kwargs)
  File "C:\Users\Crn96\Desktop\client proj\poolmasters\myauth\views.py", line 48, in home
    return render(request, "myauth/home.html", context)
  File "C:\Users\Crn96\Desktop\client proj\poolmasters\senv\lib\site-packages\django\shortcuts.py", line 24, in render
    content = loader.render_to_string(template_name, context, request, using=using)
  File "C:\Users\Crn96\Desktop\client proj\poolmasters\senv\lib\site-packages\django\template\loader.py", line 61, in render_to_string
    template = get_template(template_name, using=using)
  File "C:\Users\Crn96\Desktop\client proj\poolmasters\senv\lib\site-packages\django\template\loader.py", line 19, in get_template
    raise TemplateDoesNotExist(template_name, chain=chain)
django.template.exceptions.TemplateDoesNotExist: myauth/home.html
"GET / HTTP/1.1" 500 84868
Internal Server Error: /
Traceback (most recent call last):
  File "C:\Users\Crn96\Desktop\client proj\poolmasters\senv\lib\site-packages\django\core\handlers\exception.py", line 56, in inner
    response = get_response(request)
  File "C:\Users\Crn96\Desktop\client proj\poolmasters\senv\lib\site-packages\django\core\handlers\base.py", line 197, in _get_response
    response = wrapped_callback(request, *callback_args, **callback_kwargs)
  File "C:\Users\Crn96\Desktop\client proj\poolmasters\myauth\views.py", line 48, in home
    return render(request, "myauth/home.html", context)
  File "C:\Users\Crn96\Desktop\client proj\poolmasters\senv\lib\site-packages\django\shortcuts.py", line 24, in render
    content = loader.render_to_string(template_name, context, request, using=using)
  File "C:\Users\Crn96\Desktop\client proj\poolmasters\senv\lib\site-packages\django\template\loader.py", line 61, in render_to_string
    template = get_template(template_name, using=using)
  File "C:\Users\Crn96\Desktop\client proj\poolmasters\senv\lib\site-packages\django\template\loader.py", line 19, in get_template
    raise TemplateDoesNotExist(template_name, chain=chain)
django.template.exceptions.TemplateDoesNotExist: myauth/home.html
"GET / HTTP/1.1" 500 85246
Internal Server Error: /
Traceback (most recent call last):
  File "C:\Users\Crn96\Desktop\client proj\poolmasters\senv\lib\site-packages\django\core\handlers\exception.py", line 56, in inner
    response = get_response(request)
  File "C:\Users\Crn96\Desktop\client proj\poolmasters\senv\lib\site-packages\django\core\handlers\base.py", line 197, in _get_response
    response = wrapped_callback(request, *callback_args, **callback_kwargs)
  File "C:\Users\Crn96\Desktop\client proj\poolmasters\myauth\views.py", line 48, in home
    return render(request, "myauth/home.html", context)
  File "C:\Users\Crn96\Desktop\client proj\poolmasters\senv\lib\site-packages\django\shortcuts.py", line 24, in render
    content = loader.render_to_string(template_name, context, request, using=using)
  File "C:\Users\Crn96\Desktop\client proj\poolmasters\senv\lib\site-packages\django\template\loader.py", line 61, in render_to_string
    template = get_template(template_name, using=using)
  File "C:\Users\Crn96\Desktop\client proj\poolmasters\senv\lib\site-packages\django\template\loader.py", line 19, in get_template
    raise TemplateDoesNotExist(template_name, chain=chain)
django.template.exceptions.TemplateDoesNotExist: myauth/home.html
"GET / HTTP/1.1" 500 85246
Internal Server Error: /
Traceback (most recent call last):
  File "C:\Users\Crn96\Desktop\client proj\poolmasters\senv\lib\site-packages\django\core\handlers\exception.py", line 56, in inner
    response = get_response(request)
  File "C:\Users\Crn96\Desktop\client proj\poolmasters\senv\lib\site-packages\django\core\handlers\base.py", line 197, in _get_response
    response = wrapped_callback(request, *callback_args, **callback_kwargs)
  File "C:\Users\Crn96\Desktop\client proj\poolmasters\myauth\views.py", line 48, in home
    return render(request, "myauth/home.html", context)
  File "C:\Users\Crn96\Desktop\client proj\poolmasters\senv\lib\site-packages\django\shortcuts.py", line 24, in render
    content = loader.render_to_string(template_name, context, request, using=using)
  File "C:\Users\Crn96\Desktop\client proj\poolmasters\senv\lib\site-packages\django\template\loader.py", line 61, in render_to_string
    template = get_template(template_name, using=using)
  File "C:\Users\Crn96\Desktop\client proj\poolmasters\senv\lib\site-packages\django\template\loader.py", line 19, in get_template
    raise TemplateDoesNotExist(template_name, chain=chain)
django.template.exceptions.TemplateDoesNotExist: myauth/home.html
"GET / HTTP/1.1" 500 85246
Internal Server Error: /
Traceback (most recent call last):
  File "C:\Users\Crn96\Desktop\client proj\poolmasters\senv\lib\site-packages\django\template\base.py", line 505, in parse
    compile_func = self.tags[command]
KeyError: 'static'

During handling of the above exception, another exception occurred:

Traceback (most recent call last):
  File "C:\Users\Crn96\Desktop\client proj\poolmasters\senv\lib\site-packages\django\core\handlers\exception.py", line 56, in inner
    response = get_response(request)
  File "C:\Users\Crn96\Desktop\client proj\poolmasters\senv\lib\site-packages\django\core\handlers\base.py", line 197, in _get_response
    response = wrapped_callback(request, *callback_args, **callback_kwargs)
  File "C:\Users\Crn96\Desktop\client proj\poolmasters\myauth\views.py", line 27, in home
    return render(request, "basic/home.html", context)
  File "C:\Users\Crn96\Desktop\client proj\poolmasters\senv\lib\site-packages\django\shortcuts.py", line 24, in render
    content = loader.render_to_string(template_name, context, request, using=using)
  File "C:\Users\Crn96\Desktop\client proj\poolmasters\senv\lib\site-packages\django\template\loader.py", line 62, in render_to_string
    return template.render(context, request)
  File "C:\Users\Crn96\Desktop\client proj\poolmasters\senv\lib\site-packages\django\template\backends\django.py", line 61, in render
    return self.template.render(context)
  File "C:\Users\Crn96\Desktop\client proj\poolmasters\senv\lib\site-packages\django\template\base.py", line 175, in render
    return self._render(context)
  File "C:\Users\Crn96\Desktop\client proj\poolmasters\senv\lib\site-packages\django\template\base.py", line 167, in _render
    return self.nodelist.render(context)
  File "C:\Users\Crn96\Desktop\client proj\poolmasters\senv\lib\site-packages\django\template\base.py", line 1005, in render
    return SafeString("".join([node.render_annotated(context) for node in self]))
  File "C:\Users\Crn96\Desktop\client proj\poolmasters\senv\lib\site-packages\django\template\base.py", line 1005, in <listcomp>
    return SafeString("".join([node.render_annotated(context) for node in self]))
  File "C:\Users\Crn96\Desktop\client proj\poolmasters\senv\lib\site-packages\django\template\base.py", line 966, in render_annotated
    return self.render(context)
  File "C:\Users\Crn96\Desktop\client proj\poolmasters\senv\lib\site-packages\django\template\loader_tags.py", line 132, in render
    compiled_parent = self.get_parent(context)
  File "C:\Users\Crn96\Desktop\client proj\poolmasters\senv\lib\site-packages\django\template\loader_tags.py", line 129, in get_parent
    return self.find_template(parent, context)
  File "C:\Users\Crn96\Desktop\client proj\poolmasters\senv\lib\site-packages\django\template\loader_tags.py", line 107, in find_template
    template, origin = context.template.engine.find_template(
  File "C:\Users\Crn96\Desktop\client proj\poolmasters\senv\lib\site-packages\django\template\engine.py", line 157, in find_template
    template = loader.get_template(name, skip=skip)
  File "C:\Users\Crn96\Desktop\client proj\poolmasters\senv\lib\site-packages\django\template\loaders\cached.py", line 57, in get_template
    template = super().get_template(template_name, skip)
  File "C:\Users\Crn96\Desktop\client proj\poolmasters\senv\lib\site-packages\django\template\loaders\base.py", line 28, in get_template
    return Template(
  File "C:\Users\Crn96\Desktop\client proj\poolmasters\senv\lib\site-packages\django\template\base.py", line 154, in __init__
    self.nodelist = self.compile_nodelist()
  File "C:\Users\Crn96\Desktop\client proj\poolmasters\senv\lib\site-packages\django\template\base.py", line 200, in compile_nodelist
    return parser.parse()
  File "C:\Users\Crn96\Desktop\client proj\poolmasters\senv\lib\site-packages\django\template\base.py", line 507, in parse
    self.invalid_block_tag(token, command, parse_until)
  File "C:\Users\Crn96\Desktop\client proj\poolmasters\senv\lib\site-packages\django\template\base.py", line 568, in invalid_block_tag
    raise self.error(
django.template.exceptions.TemplateSyntaxError: Invalid block tag on line 27: 'static'. Did you forget to register or load this tag?
"GET / HTTP/1.1" 500 183363
Invalid HTTP_HOST header: '192.168.8.129:8009'. You may need to add '192.168.8.129' to ALLOWED_HOSTS.
Traceback (most recent call last):
  File "C:\Users\Crn96\Desktop\client proj\poolmasters\senv\lib\site-packages\django\core\handlers\exception.py", line 56, in inner
    response = get_response(request)
  File "C:\Users\Crn96\Desktop\client proj\poolmasters\senv\lib\site-packages\django\utils\deprecation.py", line 135, in __call__
    response = self.process_request(request)
  File "C:\Users\Crn96\Desktop\client proj\poolmasters\senv\lib\site-packages\django\middleware\common.py", line 48, in process_request
    host = request.get_host()
  File "C:\Users\Crn96\Desktop\client proj\poolmasters\senv\lib\site-packages\django\http\request.py", line 152, in get_host
    raise DisallowedHost(msg)
django.core.exceptions.DisallowedHost: Invalid HTTP_HOST header: '192.168.8.129:8009'. You may need to add '192.168.8.129' to ALLOWED_HOSTS.
Invalid HTTP_HOST header: '192.168.8.129:8009'. You may need to add '192.168.8.129' to ALLOWED_HOSTS.
Traceback (most recent call last):
  File "C:\Users\Crn96\Desktop\client proj\poolmasters\senv\lib\site-packages\django\core\handlers\exception.py", line 56, in inner
    response = get_response(request)
  File "C:\Users\Crn96\Desktop\client proj\poolmasters\senv\lib\site-packages\django\utils\deprecation.py", line 135, in __call__
    response = self.process_request(request)
  File "C:\Users\Crn96\Desktop\client proj\poolmasters\senv\lib\site-packages\django\middleware\common.py", line 48, in process_request
    host = request.get_host()
  File "C:\Users\Crn96\Desktop\client proj\poolmasters\senv\lib\site-packages\django\http\request.py", line 152, in get_host
    raise DisallowedHost(msg)
django.core.exceptions.DisallowedHost: Invalid HTTP_HOST header: '192.168.8.129:8009'. You may need to add '192.168.8.129' to ALLOWED_HOSTS.
